Workbook

Sheet List of HBM Equipment
A2: LOADCELLS | G2: Booked Out
A3: Type | B3: Asset Number | C3: Serial Number | D3: Range | E3: Cost-Point used with Purchase | F3: Remarks | G3: Name | H3: Student Number | I3: Date Taken
A4: Round Type-U2A | B4: '400064'!A1 | C4: B73498 | D4: 10kN - 1000kg | E4: 0280 | G4: {=OFFSET('400064'!F$1, MAX(ROW('400064'!F:F)*('400064'!F:F<>"")-1),0)} -> E Stockhalm | H4: {=OFFSET('400064'!G$1, MAX(ROW('400064'!G:G)*('400064'!G:G<>"")-1),0)} -> 23648341 | I4: {=OFFSET('400064'!H$1, MAX(ROW('400064'!H:H)*('400064'!H:H<>"")-1),0)} -> 18/08/2025 | J4: {=OFFSET('400064'!I$1, MAX(ROW('400064'!I:I)*('400064'!I:I<>"")-1),0)} -> RETURNED
A5: Round Type-U2A | B5: '400065'!A1 | C5: C16754 | D5: 10kN - 1000kg | E5: 0280 | G5: {=OFFSET('400065'!F$1, MAX(ROW('400065'!F:F)*('400065'!F:F<>"")-1),0)} -> A. Turner | H5: {=OFFSET('400065'!G$1, MAX(ROW('400065'!G:G)*('400065'!G:G<>"")-1),0)} -> 25928333 | I5: {=OFFSET('400065'!H$1, MAX(ROW('400065'!H:H)*('400065'!H:H<>"")-1),0)} -> 45938 | J5: {=OFFSET('400065'!I$1, MAX(ROW('400065'!I:I)*('400065'!I:I<>"")-1),0)} -> RETURNED
A6: Round Type-U2A | B6: '400067'!A1 | C6: F23715 | D6: 10kN - 1000kg | E6: 0280 | G6: {=OFFSET('400067'!F$1, MAX(ROW('400067'!F:F)*('400067'!F:F<>"")-1),0)} -> M. Nimb | H6: {=OFFSET('400067'!G$1, MAX(ROW('400067'!G:G)*('400067'!G:G<>"")-1),0)} -> 24776661 | I6: {=OFFSET('400067'!H$1, MAX(ROW('400067'!H:H)*('400067'!H:H<>"")-1),0)} -> 45938 | J6: {=OFFSET('400067'!I$1, MAX(ROW('400067'!I:I)*('400067'!I:I<>"")-1),0)} -> RETURNED
A7: Round Type-U2A | B7: '400066'!A1 | C7: E99828 | D7: 2kN - 200kg | E7: 0280 | F7: Broken | G7: {=OFFSET('400066'!F$1, MAX(ROW('400066'!F:F)*('400066'!F:F<>"")-1),0)} -> M. Nimb | H7: {=OFFSET('400066'!G$1, MAX(ROW('400066'!G:G)*('400066'!G:G<>"")-1),0)} -> 24776661 | I7: {=OFFSET('400066'!H$1, MAX(ROW('400066'!H:H)*('400066'!H:H<>"")-1),0)} -> 26/08/2025 | J7: {=OFFSET('400066'!I$1, MAX(ROW('400066'!I:I)*('400066'!I:I<>"")-1),0)} -> RETURNED
A8: Round Type | B8: '408763'!A1 | C8: 088671 | D8: 500N - 50kg | E8: 0280N | G8: {=OFFSET('408763'!F$1, MAX(ROW('408763'!F:F)*('408763'!F:F<>"")-1),0)} -> James Ralph | H8: {=OFFSET('408763'!G$1, MAX(ROW('408763'!G:G)*('408763'!G:G<>"")-1),0)} -> 19904150 | I8: {=OFFSET('408763'!H$1, MAX(ROW('408763'!H:H)*('408763'!H:H<>"")-1),0)} -> 45080 | J8: {=OFFSET('408763'!I$1, MAX(ROW('408763'!I:I)*('408763'!I:I<>"")-1),0)} -> RETURNED
A9: Round Type | B9: '408764'!A1 | C9: 083931 | D9: 1kN - 100kg | E9: 0280N | G9: {=OFFSET('408764'!F$1, MAX(ROW('408764'!F:F)*('408764'!F:F<>"")-1),0)} -> Name | H9: {=OFFSET('408764'!G$1, MAX(ROW('408764'!G:G)*('408764'!G:G<>"")-1),0)} -> Student Number | I9: {=OFFSET('408764'!H$1, MAX(ROW('408764'!H:H)*('408764'!H:H<>"")-1),0)} -> Date Taken | J9: {=OFFSET('408764'!I$1, MAX(ROW('408764'!I:I)*('408764'!I:I<>"")-1),0)} -> Date Returned
A10: U2AD1/2T - Round Type | B10: '485376'!A1 | C10: 026925 | D10: 20kN - 2000kg | G10: {=OFFSET('485376'!F$1, MAX(ROW('485376'!F:F)*('485376'!F:F<>"")-1),0)} -> JW Van Santen | H10: {=OFFSET('485376'!G$1, MAX(ROW('485376'!G:G)*('485376'!G:G<>"")-1),0)} -> 18326498 | I10: {=OFFSET('485376'!H$1, MAX(ROW('485376'!H:H)*('485376'!H:H<>"")-1),0)} -> 20/07/2020 | J10: {=OFFSET('485376'!I$1, MAX(ROW('485376'!I:I)*('485376'!I:I<>"")-1),0)} -> RETURNED
A11: U2AD1/2T - Round Type | B11: '485377'!A1 | C11: 028563 | D11: 20kN - 2000kg | G11: {=OFFSET('485377'!F$1, MAX(ROW('485377'!F:F)*('485377'!F:F<>"")-1),0)} -> JW Van Santen | H11: {=OFFSET('485377'!G$1, MAX(ROW('485377'!G:G)*('485377'!G:G<>"")-1),0)} -> 18326498 | I11: {=OFFSET('485377'!H$1, MAX(ROW('485377'!H:H)*('485377'!H:H<>"")-1),0)} -> 20/07/2020 | J11: {=OFFSET('485377'!I$1, MAX(ROW('485377'!I:I)*('485377'!I:I<>"")-1),0)} -> RETURNED
A13: Z-Type SM2 | B13: '443733'!A1 | C13: 02718726 | D13: 50N - 5kg | E13: 0280N | G13: {=OFFSET('443733'!F$1, MAX(ROW('443733'!F:F)*('443733'!F:F<>"")-1),0)} -> AV Covoy | H13: {=OFFSET('443733'!G$1, MAX(ROW('443733'!G:G)*('443733'!G:G<>"")-1),0)} -> 19774869 | I13: {=OFFSET('443733'!H$1, MAX(ROW('443733'!H:H)*('443733'!H:H<>"")-1),0)} -> 44540 | J13: {=OFFSET('443733'!I$1, MAX(ROW('443733'!I:I)*('443733'!I:I<>"")-1),0)} -> RETURNED
A14: Z-Type SM2 | B14: '443734'!A1 | C14: 02718733 | D14: 50N - 5kg | E14: 0280N | G14: {=OFFSET('443734'!F$1, MAX(ROW('443734'!F:F)*('443734'!F:F<>"")-1),0)} -> Steenkamp | H14: {=OFFSET('443734'!G$1, MAX(ROW('443734'!G:G)*('443734'!G:G<>"")-1),0)} -> 19777701 | I14: {=OFFSET('443734'!H$1, MAX(ROW('443734'!H:H)*('443734'!H:H<>"")-1),0)} -> 44443 | J14: {=OFFSET('443734'!I$1, MAX(ROW('443734'!I:I)*('443734'!I:I<>"")-1),0)} -> 18/05/2021
A15: Z-Type SM2 | B15: '443735'!A1 | C15: 02718686 | D15: 50N - 5kg | E15: 0280N | G15: {=OFFSET('443735'!F$1, MAX(ROW('443735'!F:F)*('443735'!F:F<>"")-1),0)} -> L De Wet | H15: {=OFFSET('443735'!G$1, MAX(ROW('443735'!G:G)*('443735'!G:G<>"")-1),0)} -> 23743468 | I15: {=OFFSET('443735'!H$1, MAX(ROW('443735'!H:H)*('443735'!H:H<>"")-1),0)} -> 44812 | J15: {=OFFSET('443735'!I$1, MAX(ROW('443735'!I:I)*('443735'!I:I<>"")-1),0)} -> RETURNED
A16: Z-Type SM2 | B16: '443736'!A1 | C16: 02918009 | D16: 50N - 5kg | E16: 0280N | G16: {=OFFSET('443736'!F$1, MAX(ROW('443736'!F:F)*('443736'!F:F<>"")-1),0)} -> L De Wet | H16: {=OFFSET('443736'!G$1, MAX(ROW('443736'!G:G)*('443736'!G:G<>"")-1),0)} -> 23743468 | I16: {=OFFSET('443736'!H$1, MAX(ROW('443736'!H:H)*('443736'!H:H<>"")-1),0)} -> 21/08/2023 | J16: {=OFFSET('443736'!I$1, MAX(ROW('443736'!I:I)*('443736'!I:I<>"")-1),0)} -> RETURNED
A17: Z-Type SM2 | B17: '443610'!A1 | C17: 02918017 | D17: 50N - 5kg | E17: 0284N | G17: {=OFFSET('443610'!F$1, MAX(ROW('443610'!F:F)*('443610'!F:F<>"")-1),0)} -> G Stephan | H17: {=OFFSET('443610'!G$1, MAX(ROW('443610'!G:G)*('443610'!G:G<>"")-1),0)} -> 20150679 | I17: {=OFFSET('443610'!H$1, MAX(ROW('443610'!H:H)*('443610'!H:H<>"")-1),0)} -> 15/09/2020 | J17: {=OFFSET('443610'!I$1, MAX(ROW('443610'!I:I)*('443610'!I:I<>"")-1),0)} -> 29/01/2021
A19: Z-Type SM2 | B19: '443737'!A1 | C19: 02549146 | D19: 100N - 10kg | E19: 0280N | F19: Broken | G19: {=OFFSET('443737'!F$1, MAX(ROW('443737'!F:F)*('443737'!F:F<>"")-1),0)} -> Name | H19: {=OFFSET('443737'!G$1, MAX(ROW('443737'!G:G)*('443737'!G:G<>"")-1),0)} -> Student Number | I19: {=OFFSET('443737'!H$1, MAX(ROW('443737'!H:H)*('443737'!H:H<>"")-1),0)} -> Date Taken | J19: {=OFFSET('443737'!I$1, MAX(ROW('443737'!I:I)*('443737'!I:I<>"")-1),0)} -> Date Returned
A20: Z-Type SM2 | B20: '443738'!A1 | C20: 02718704 | D20: 100N - 10kg | E20: 0280N | G20: {=OFFSET('443738'!F$1, MAX(ROW('443738'!F:F)*('443738'!F:F<>"")-1),0)} -> Name | H20: {=OFFSET('443738'!G$1, MAX(ROW('443738'!G:G)*('443738'!G:G<>"")-1),0)} -> Student Number | I20: {=OFFSET('443738'!H$1, MAX(ROW('443738'!H:H)*('443738'!H:H<>"")-1),0)} -> Date Taken | J20: {=OFFSET('443738'!I$1, MAX(ROW('443738'!I:I)*('443738'!I:I<>"")-1),0)} -> Date Returned
A21: Z-Type SM2 | B21: '443739'!A1 | C21: 02718813 | D21: 100N - 10kg | E21: 0280N | G21: {=OFFSET('443739'!F$1, MAX(ROW('443739'!F:F)*('443739'!F:F<>"")-1),0)} -> E Stockhalm | H21: {=OFFSET('443739'!G$1, MAX(ROW('443739'!G:G)*('443739'!G:G<>"")-1),0)} -> 23648341 | I21: {=OFFSET('443739'!H$1, MAX(ROW('443739'!H:H)*('443739'!H:H<>"")-1),0)} -> 20/08/2025 | J21: {=OFFSET('443739'!I$1, MAX(ROW('443739'!I:I)*('443739'!I:I<>"")-1),0)} -> OUTSTANDING
A22: Z-Type SM2 | B22: '443740'!A1 | C22: 02718808 | D22: 100N - 10kg | E22: 0280N | G22: {=OFFSET('443740'!F$1, MAX(ROW('443740'!F:F)*('443740'!F:F<>"")-1),0)} -> J Van Zyl | H22: {=OFFSET('443740'!G$1, MAX(ROW('443740'!G:G)*('443740'!G:G<>"")-1),0)} -> 20858795 | I22: {=OFFSET('443740'!H$1, MAX(ROW('443740'!H:H)*('443740'!H:H<>"")-1),0)} -> 18/08/2022 | J22: {=OFFSET('443740'!I$1, MAX(ROW('443740'!I:I)*('443740'!I:I<>"")-1),0)} -> 26/04/2023
A24: Z-Type SM2 | B24: '443741'!A1 | C24: 02917885 | D24: 200N - 20kg | E24: 0280N | F24: Broken | G24: {=OFFSET('443741'!F$1, MAX(ROW('443741'!F:F)*('443741'!F:F<>"")-1),0)} -> Name | H24: {=OFFSET('443741'!G$1, MAX(ROW('443741'!G:G)*('443741'!G:G<>"")-1),0)} -> Student Number | I24: {=OFFSET('443741'!H$1, MAX(ROW('443741'!H:H)*('443741'!H:H<>"")-1),0)} -> Date Taken | J24: {=OFFSET('443741'!I$1, MAX(ROW('443741'!I:I)*('443741'!I:I<>"")-1),0)} -> Date Returned
A25: Z-Type SM2 | B25: '443742'!A1 | C25: 02917886 | D25: 200N - 20kg | E25: 0280N | F25: Broken | G25: {=OFFSET('443742'!F$1, MAX(ROW('443742'!F:F)*('443742'!F:F<>"")-1),0)} -> CR Sauls | H25: {=OFFSET('443742'!G$1, MAX(ROW('443742'!G:G)*('443742'!G:G<>"")-1),0)} -> 20778465 | I25: {=OFFSET('443742'!H$1, MAX(ROW('443742'!H:H)*('443742'!H:H<>"")-1),0)} -> 14/10/2021 | J25: RETURNED
A26: Z-Type SM2 | B26: '443743'!A1 | C26: 02917896 | D26: 200N - 20kg | E26: 0280N | F26: Broken | G26: {=OFFSET('443743'!F$1, MAX(ROW('443743'!F:F)*('443743'!F:F<>"")-1),0)} -> Name | H26: {=OFFSET('443743'!G$1, MAX(ROW('443743'!G:G)*('443743'!G:G<>"")-1),0)} -> Student Number | I26: {=OFFSET('443743'!H$1, MAX(ROW('443743'!H:H)*('443743'!H:H<>"")-1),0)} -> Date Taken | J26: {=OFFSET('443743'!I$1, MAX(ROW('443743'!I:I)*('443743'!I:I<>"")-1),0)} -> Date Returned
A27: Z-Type SM2 | B27: '443744'!A1 | C27: 02917906 | D27: 200N - 20kg | E27: 0280N | G27: {=OFFSET('443744'!F$1, MAX(ROW('443744'!F:F)*('443744'!F:F<>"")-1),0)} -> Josua Van Tonder | H27: {=OFFSET('443744'!G$1, MAX(ROW('443744'!G:G)*('443744'!G:G<>"")-1),0)} -> 21059721 | I27: {=OFFSET('443744'!H$1, MAX(ROW('443744'!H:H)*('443744'!H:H<>"")-1),0)} -> 16/09/2022 | J27: {=OFFSET('443744'!I$1, MAX(ROW('443744'!I:I)*('443744'!I:I<>"")-1),0)} -> 45055
G28: Petrus Haasbroek | H28: 19855400 | I28: 44603 | J28: {=OFFSET('443744'!I$1, MAX(ROW('443744'!I:I)*('443744'!I:I<>"")-1),0)} -> 45055
A29: Z-Type SM2 | B29: '443745'!A1 | C29: 31050691 | D29: 1kN - 100kg | E29: 0280N | G29: {=OFFSET('443745'!F$1, MAX(ROW('443745'!F:F)*('443745'!F:F<>"")-1),0)} -> Nadeem Davids | H29: {=OFFSET('443745'!G$1, MAX(ROW('443745'!G:G)*('443745'!G:G<>"")-1),0)} -> 21160503 | I29: {=OFFSET('443745'!H$1, MAX(ROW('443745'!H:H)*('443745'!H:H<>"")-1),0)} -> 45149 | J29: {=OFFSET('443745'!I$1, MAX(ROW('443745'!I:I)*('443745'!I:I<>"")-1),0)} -> 14/08/2023
A30: Z-Type SM2 | B30: '443748'!A1 | C30: 31137976 | D30: 1kN - 100kg | E30: 0280N | F30: Broken | G30: {=OFFSET('443748'!F$1, MAX(ROW('443748'!F:F)*('443748'!F:F<>"")-1),0)} -> Name | H30: {=OFFSET('443748'!G$1, MAX(ROW('443748'!G:G)*('443748'!G:G<>"")-1),0)} -> Student Number | I30: {=OFFSET('443748'!H$1, MAX(ROW('443748'!H:H)*('443748'!H:H<>"")-1),0)} -> Date Taken | J30: {=OFFSET('443748'!I$1, MAX(ROW('443748'!I:I)*('443748'!I:I<>"")-1),0)} -> Date Returned
A32: Z-Type SM2 | B32: '443746'!A1 | C32: 31127524 | D32: 5kN - 500kg | E32: 0280N | G32: {=OFFSET('443746'!F$1, MAX(ROW('443746'!F:F)*('443746'!F:F<>"")-1),0)} -> PC Swanepoel | H32: {=OFFSET('443746'!G$1, MAX(ROW('443746'!G:G)*('443746'!G:G<>"")-1),0)} -> 16622766 | I32: {=OFFSET('443746'!H$1, MAX(ROW('443746'!H:H)*('443746'!H:H<>"")-1),0)} -> 45758 | J32: {=OFFSET('443746'!I$1, MAX(ROW('443746'!I:I)*('443746'!I:I<>"")-1),0)} -> RETURNED
A33: Z-Type SM2 | B33: '443747'!A1 | C33: 31127531 | D33: 5kN - 500kg | E33: 0280N | F33: Broken | G33: {=OFFSET('443747'!F$1, MAX(ROW('443747'!F:F)*('443747'!F:F<>"")-1),0)} -> PC SWanepoel | H33: {=OFFSET('443747'!G$1, MAX(ROW('443747'!G:G)*('443747'!G:G<>"")-1),0)} -> 16622766 | I33: {=OFFSET('443747'!H$1, MAX(ROW('443747'!H:H)*('443747'!H:H<>"")-1),0)} -> 45756 | J33: {=OFFSET('443747'!I$1, MAX(ROW('443747'!I:I)*('443747'!I:I<>"")-1),0)} -> RETURNED
A35: U2B 200kN | B35: '459962'!A1 | C35: N79647 | D35: 200kN | E35: 0280N | G35: {=OFFSET('459962'!F$1, MAX(ROW('459962'!F:F)*('459962'!F:F<>"")-1),0)} -> JW van Santen | H35: {=OFFSET('459962'!G$1, MAX(ROW('459962'!G:G)*('459962'!G:G<>"")-1),0)} -> 18326498 | I35: {=OFFSET('459962'!H$1, MAX(ROW('459962'!H:H)*('459962'!H:H<>"")-1),0)} -> 43787 | J35: {=OFFSET('459962'!I$1, MAX(ROW('459962'!I:I)*('459962'!I:I<>"")-1),0)} -> RETURNED
A36: U2B 100kN | B36: '459961'!A1 | C36: N87983 | D36: 100kN | E36: 0280N | G36: {=OFFSET('459961'!F$1, MAX(ROW('459961'!F:F)*('459961'!F:F<>"")-1),0)} -> JW van Santen | H36: {=OFFSET('459961'!G$1, MAX(ROW('459961'!G:G)*('459961'!G:G<>"")-1),0)} -> 18326498 | I36: {=OFFSET('459961'!H$1, MAX(ROW('459961'!H:H)*('459961'!H:H<>"")-1),0)} -> 43787 | J36: {=OFFSET('459961'!I$1, MAX(ROW('459961'!I:I)*('459961'!I:I<>"")-1),0)} -> RETURNED
A37: U2B 50kN | B37: '459960'!A1 | C37: N99085 | D37: 50kN | E37: 0280N | G37: {=OFFSET('459960'!F$1, MAX(ROW('459960'!F:F)*('459960'!F:F<>"")-1),0)} -> Daniel Raats | H37: {=OFFSET('459960'!G$1, MAX(ROW('459960'!G:G)*('459960'!G:G<>"")-1),0)} -> 21645655 | I37: {=OFFSET('459960'!H$1, MAX(ROW('459960'!H:H)*('459960'!H:H<>"")-1),0)} -> 45415 | J37: {=OFFSET('459960'!I$1, MAX(ROW('459960'!I:I)*('459960'!I:I<>"")-1),0)} -> RETURNED
A38: U2B 20kN | B38: '459959'!A1 | C38: N93342 | D38: 20kN | E38: 0280N | G38: {=OFFSET('459959'!F$1, MAX(ROW('459959'!F:F)*('459959'!F:F<>"")-1),0)} -> R Louw | H38: {=OFFSET('459959'!G$1, MAX(ROW('459959'!G:G)*('459959'!G:G<>"")-1),0)} -> 22550798 | I38: {=OFFSET('459959'!H$1, MAX(ROW('459959'!H:H)*('459959'!H:H<>"")-1),0)} -> 14/09/2022 | J38: {=OFFSET('459959'!I$1, MAX(ROW('459959'!I:I)*('459959'!I:I<>"")-1),0)} -> RETURNED
A40: S9M/10kN | B40: '487810'!A1 | C40: 31733148 | D40: 10kN - 1000kg | G40: {=OFFSET('487810'!F$1, MAX(ROW('487810'!F:F)*('487810'!F:F<>"")-1),0)} -> C vd Westhuizen | H40: {=OFFSET('487810'!G$1, MAX(ROW('487810'!G:G)*('487810'!G:G<>"")-1),0)} -> 24194379 | I40: {=OFFSET('487810'!H$1, MAX(ROW('487810'!H:H)*('487810'!H:H<>"")-1),0)} -> 45777 | J40: {=OFFSET('487810'!I$1, MAX(ROW('487810'!I:I)*('487810'!I:I<>"")-1),0)} -> RETURNED
A42: U9C/2kN | B42: '468620'!A1 | C42: 211010672 | D42: 2kN - 200kg | G42: {=OFFSET('468620'!F$1, MAX(ROW('468620'!F:F)*('468620'!F:F<>"")-1),0)} -> Josua Van Tonder | H42: {=OFFSET('468620'!G$1, MAX(ROW('468620'!G:G)*('468620'!G:G<>"")-1),0)} -> 1902243 | I42: {=OFFSET('468620'!H$1, MAX(ROW('468620'!H:H)*('468620'!H:H<>"")-1),0)} -> 44175 | J42: {=OFFSET('468620'!I$1, MAX(ROW('468620'!I:I)*('468620'!I:I<>"")-1),0)} -> RETURNED
A43: SP4C3 | C43: 00495870 | D43: 20kg
A44: SP4C3 | C44: 01373560 | D44: 20kg
A45: SP4C3 | C45: 29306036 | D45: 20kg
A46: SP4C3 | C46: 29330086 | D46: 20kg
A47: SP4C3 | C47: 11602081 | D47: 30kg
A48: SPM4C3MR | C48: 02184452 | D48: 30kg
...

Sheet 437406
A1: ='List of HBM Equipment'!A205 -> Type | B1: ='List of HBM Equipment'!B205 -> Model | C1: ='List of HBM Equipment'!C412 -> Asset number | F1: Booked Out
A2: ='List of HBM Equipment'!A101 -> MX840B | B2: ='List of HBM Equipment'!B101 -> 437406'!A1 | C2: 437406 | F2: Name | G2: Student Number | H2: Date Taken | I2: Date Returned
F3: Llewellyn | G3: 22793429 | H3: 45744 | I3: Back
F4: Mr. J Bredell | H4: 45874 | I4: RETURNED
B5: Click to return to HOME

Sheet 536093
A1: ='List of HBM Equipment'!A205 -> Type | B1: ='List of HBM Equipment'!B205 -> Model | C1: ='List of HBM Equipment'!C412 -> Asset number | F1: Booked Out
A2: ='List of HBM Equipment'!A100 -> MX460B | B2: ='List of HBM Equipment'!B100 -> 536093'!A1 | C2: 536093 | F2: Name | G2: Student Number | H2: Date Taken | I2: Date Returned
F3: Llewellyn | G3: 22793429 | H3: 45744 | I3: Back
B5: Click to return to HOME

Sheet 435608
A1: ='List of HBM Equipment'!A205 -> Type | B1: ='List of HBM Equipment'!B205 -> Model | C1: ='List of HBM Equipment'!C412 -> Asset number | E1: Booked Out
A2: ='List of HBM Equipment'!A447 -> Endress+Hauser | B2: ='List of HBM Equipment'!B447 -> Deltabar S PMD75 | C2: 435608 | E2: Name | F2: Student Number | G2: Date Taken | H2: Date Returned
B5: Click to return to HOME

Sheet 435602
A1: ='List of HBM Equipment'!A205 -> Type | B1: ='List of HBM Equipment'!B205 -> Model | C1: ='List of HBM Equipment'!C412 -> Asset number | E1: Booked Out
A2: ='List of HBM Equipment'!A446 -> Endress+Hauser | B2: ='List of HBM Equipment'!B446 -> Deltabar S PMD75 | C2: 435602 | E2: Name | F2: Student Number | G2: Date Taken | H2: Date Returned
B5: Click to return to HOME

Sheet 435605
A1: ='List of HBM Equipment'!A205 -> Type | B1: ='List of HBM Equipment'!B205 -> Model | C1: ='List of HBM Equipment'!C412 -> Asset number | E1: Booked Out
A2: ='List of HBM Equipment'!A445 -> Endress+Hauser | B2: ='List of HBM Equipment'!B445 -> Deltabar S PMD75 | C2: 435605 | E2: Name | F2: Student Number | G2: Date Taken | H2: Date Returned
B5: Click to return to HOME

Sheet 435604
A1: ='List of HBM Equipment'!A205 -> Type | B1: ='List of HBM Equipment'!B205 -> Model | C1: ='List of HBM Equipment'!C412 -> Asset number | E1: Booked Out
A2: ='List of HBM Equipment'!A444 -> Endress+Hauser | B2: ='List of HBM Equipment'!B444 -> Deltabar S PMD75 | C2: 435604 | E2: Name | F2: Student Number | G2: Date Taken | H2: Date Returned
B5: Click to return to HOME

Sheet 400194
A1: ='List of HBM Equipment'!A205 -> Type | B1: ='List of HBM Equipment'!B205 -> Model | C1: ='List of HBM Equipment'!C412 -> Asset number | E1: Booked Out
A2: ='List of HBM Equipment'!A440 -> Endress+Hauser | B2: ='List of HBM Equipment'!B440 -> Deltabar S PMD70 | C2: 347205 | E2: Name | F2: Student Number | G2: Date Taken | H2: Date Returned
B5: Click to return to HOME

Sheet 347205
A1: ='List of HBM Equipment'!A205 -> Type | B1: ='List of HBM Equipment'!B205 -> Model | C1: ='List of HBM Equipment'!C412 -> Asset number | E1: Booked Out
A2: ='List of HBM Equipment'!A440 -> Endress+Hauser | B2: ='List of HBM Equipment'!B440 -> Deltabar S PMD70 | C2: 347205 | E2: Name | F2: Student Number | G2: Date Taken | H2: Date Returned
B5: Click to return to HOME

Sheet 435496
A1: ='List of HBM Equipment'!A205 -> Type | B1: ='List of HBM Equipment'!B205 -> Model | C1: ='List of HBM Equipment'!C412 -> Asset number | E1: Booked Out
A2: ='List of HBM Equipment'!A436 -> Agilent | B2: ='List of HBM Equipment'!B436 -> 34972A | C2: 435496 | E2: Name | F2: Student Number | G2: Date Taken | H2: Date Returned
B5: Click to return to HOME

Sheet 312992
A1: ='List of HBM Equipment'!A205 -> Type | B1: ='List of HBM Equipment'!B205 -> Model | C1: ='List of HBM Equipment'!C412 -> Asset number | E1: Booked Out
A2: ='List of HBM Equipment'!A429 -> Endress+Hauser | B2: ='List of HBM Equipment'!B429 -> Deltabar S PMD230 | C2: 312992 | E2: Name | F2: Student Number | G2: Date Taken | H2: Date Returned
B5: Click to return to HOME

Sheet 435606
A1: ='List of HBM Equipment'!A205 -> Type | B1: ='List of HBM Equipment'!B205 -> Model | C1: ='List of HBM Equipment'!C412 -> Asset number | E1: Booked Out
A2: ='List of HBM Equipment'!A428 -> Endress+Hauser | B2: ='List of HBM Equipment'!B428 -> Deltabar S PMD75 | C2: 435606 | E2: Name | F2: Student Number | G2: Date Taken | H2: Date Returned
B5: Click to return to HOME

Sheet 312994
A1: ='List of HBM Equipment'!A205 -> Type | B1: ='List of HBM Equipment'!B205 -> Model | C1: ='List of HBM Equipment'!C412 -> Asset number | E1: Booked Out
A2: ='List of HBM Equipment'!A427 -> Endress+Hauser | B2: ='List of HBM Equipment'!B427 -> Deltabar S PMD230 | C2: 312994 | E2: Name | F2: Student Number | G2: Date Taken | H2: Date Returned
B5: Click to return to HOME

Sheet 450517
A1: ='List of HBM Equipment'!A205 -> Type | B1: ='List of HBM Equipment'!B205 -> Model | C1: ='List of HBM Equipment'!C412 -> Asset number | E1: Booked Out
A2: ='List of HBM Equipment'!A420 -> Endress+Hauser | B2: ='List of HBM Equipment'!B420 -> Deltabar S PMD75 | C2: 450517 | E2: Name | F2: Student Number | G2: Date Taken | H2: Date Returned
B5: Click to return to HOME

Sheet 450520
A1: ='List of HBM Equipment'!A205 -> Type | B1: ='List of HBM Equipment'!B205 -> Model | C1: ='List of HBM Equipment'!C412 -> Asset number | E1: Booked Out
A2: ='List of HBM Equipment'!A419 -> Endress+Hauser | B2: ='List of HBM Equipment'!B419 -> Deltabar S PMD75 | C2: 450520 | E2: Name | F2: Student Number | G2: Date Taken | H2: Date Returned
B5: Click to return to HOME

Sheet 450518
A1: ='List of HBM Equipment'!A205 -> Type | B1: ='List of HBM Equipment'!B205 -> Model | C1: ='List of HBM Equipment'!C412 -> Asset number | E1: Booked Out
A2: ='List of HBM Equipment'!A418 -> Endress+Hauser | B2: ='List of HBM Equipment'!B418 -> Deltabar S PMD75 | C2: 450518 | E2: Name | F2: Student Number | G2: Date Taken | H2: Date Returned
B5: Click to return to HOME

Sheet 450519
A1: ='List of HBM Equipment'!A205 -> Type | B1: ='List of HBM Equipment'!B205 -> Model | C1: ='List of HBM Equipment'!C412 -> Asset number | E1: Booked Out
A2: ='List of HBM Equipment'!A417 -> Endress+Hauser | B2: ='List of HBM Equipment'!B417 -> Deltabar S PMD75 | C2: 450519 | E2: Name | F2: Student Number | G2: Date Taken | H2: Date Returned
B5: Click to return to HOME

Sheet 435460
A1: ='List of HBM Equipment'!A205 -> Type | B1: ='List of HBM Equipment'!B205 -> Model | C1: ='List of HBM Equipment'!C412 -> Asset number | E1: Booked Out
A2: ='List of HBM Equipment'!A413 -> Agilent | B2: ='List of HBM Equipment'!B413 -> 34972A | C2: 435460 | E2: Name | F2: Student Number | G2: Date Taken | H2: Date Returned
B5: Click to return to HOME

Sheet 469450
A1: ='List of HBM Equipment'!A205 -> Type | B1: ='List of HBM Equipment'!B205 -> Model | C1: ='List of HBM Equipment'!C400 -> B/N | E1: Booked Out
A2: ='List of HBM Equipment'!A406 -> Huato | B2: ='List of HBM Equipment'!B406 -> S220-T8 | C2: 469450 | E2: Name | F2: Student Number | G2: Date Taken | H2: Date Returned
B5: Click to return to HOME

Sheet 469449
A1: ='List of HBM Equipment'!A205 -> Type | B1: ='List of HBM Equipment'!B205 -> Model | C1: ='List of HBM Equipment'!C400 -> B/N | E1: Booked Out
A2: ='List of HBM Equipment'!A405 -> Huato | B2: ='List of HBM Equipment'!B405 -> S220-T8 | C2: 469449 | E2: Name | F2: Student Number | G2: Date Taken | H2: Date Returned
B5: Click to return to HOME

Sheet 469451
A1: ='List of HBM Equipment'!A205 -> Type | B1: ='List of HBM Equipment'!B205 -> Model | C1: ='List of HBM Equipment'!C400 -> B/N | E1: Booked Out
A2: ='List of HBM Equipment'!A404 -> Huato | B2: ='List of HBM Equipment'!B404 -> S220-T8 | C2: 469451 | E2: Name | F2: Student Number | G2: Date Taken | H2: Date Returned
B5: Click to return to HOME

Sheet 469446
A1: ='List of HBM Equipment'!A205 -> Type | B1: ='List of HBM Equipment'!B205 -> Model | C1: ='List of HBM Equipment'!C400 -> B/N | E1: Booked Out
A2: ='List of HBM Equipment'!A403 -> Huato | B2: ='List of HBM Equipment'!B403 -> S220-T8 | C2: 469446 | E2: Name | F2: Student Number | G2: Date Taken | H2: Date Returned
B5: Click to return to HOME

Sheet 469448
A1: ='List of HBM Equipment'!A205 -> Type | B1: ='List of HBM Equipment'!B205 -> Model | C1: ='List of HBM Equipment'!C400 -> B/N | E1: Booked Out
A2: ='List of HBM Equipment'!A402 -> Huato | B2: ='List of HBM Equipment'!B402 -> S220-T8 | C2: 469448 | E2: Name | F2: Student Number | G2: Date Taken | H2: Date Returned
B5: Click to return to HOME

Sheet 469453
A1: ='List of HBM Equipment'!A205 -> Type | B1: ='List of HBM Equipment'!B205 -> Model | C1: ='List of HBM Equipment'!C400 -> B/N | E1: Booked Out
A2: ='List of HBM Equipment'!A401 -> Huato | B2: ='List of HBM Equipment'!B401 -> S220-T8 | C2: 469453 | E2: Name | F2: Student Number | G2: Date Taken | H2: Date Returned
B5: Click to return to HOME

Sheet 189761
A1: ='List of HBM Equipment'!A205 -> Type | B1: ='List of HBM Equipment'!B205 -> Model | C1: ='List of HBM Equipment'!C391 -> Asset number | E1: Booked Out
A2: ='List of HBM Equipment'!A397 -> Keithley | B2: ='List of HBM Equipment'!B397 -> 197 | C2: 189761 | E2: Name | F2: Student Number | G2: Date Taken | H2: Date Returned
B5: Click to return to HOME

Sheet 189762
A1: ='List of HBM Equipment'!A205 -> Type | B1: ='List of HBM Equipment'!B205 -> Model | C1: ='List of HBM Equipment'!C391 -> Asset number | E1: Booked Out
A2: ='List of HBM Equipment'!A396 -> Keithley | B2: ='List of HBM Equipment'!B396 -> 197 | C2: 189762 | E2: Name | F2: Student Number | G2: Date Taken | H2: Date Returned
B5: Click to return to HOME

Sheet 272977
A1: ='List of HBM Equipment'!A205 -> Type | B1: ='List of HBM Equipment'!B205 -> Model | C1: ='List of HBM Equipment'!C391 -> Asset number | E1: Booked Out
A2: ='List of HBM Equipment'!A392 -> HBM | B2: ='List of HBM Equipment'!B392 -> Scout 55 | C2: 272977 | E2: Name | F2: Student Number | G2: Date Taken | H2: Date Returned
B5: Click to return to HOME

Sheet 166045
A1: ='List of HBM Equipment'!A205 -> Type | B1: ='List of HBM Equipment'!B205 -> Model | C1: ='List of HBM Equipment'!C371 -> S/N or Asset number | E1: Booked Out
A2: ='List of HBM Equipment'!A388 -> HP | B2: ='List of HBM Equipment'!B388 -> 3478A | C2: 166045 | E2: Name | F2: Student Number | G2: Date Taken | H2: Date Returned
B5: Click to return to HOME

Sheet 456548
A1: ='List of HBM Equipment'!A205 -> Type | B1: ='List of HBM Equipment'!B205 -> Model | C1: ='List of HBM Equipment'!C371 -> S/N or Asset number | E1: Booked Out
A2: ='List of HBM Equipment'!A383 -> Keysight | B2: ='List of HBM Equipment'!B383 -> 34972A | C2: 456548 | E2: Name | F2: Student Number | G2: Date Taken | H2: Date Returned
B5: Click to return to HOME

Sheet 459327
A1: ='List of HBM Equipment'!A205 -> Type | B1: ='List of HBM Equipment'!B205 -> Model | C1: ='List of HBM Equipment'!C371 -> S/N or Asset number | E1: Booked Out
A2: ='List of HBM Equipment'!A382 -> Keysight | B2: ='List of HBM Equipment'!B382 -> 34972A | C2: 459327 | E2: Name | F2: Student Number | G2: Date Taken | H2: Date Returned
B5: Click to return to HOME

Sheet MY49024748
A1: ='List of HBM Equipment'!A205 -> Type | B1: ='List of HBM Equipment'!B205 -> Model | C1: ='List of HBM Equipment'!C371 -> S/N or Asset number | E1: Booked Out
A2: ='List of HBM Equipment'!A381 -> Keysight | B2: ='List of HBM Equipment'!B381 -> 34972A | C2: MY49024748 | E2: Name | F2: Student Number | G2: Date Taken | H2: Date Returned
B5: Click to return to HOME

Sheet 247446
A1: ='List of HBM Equipment'!A205 -> Type | B1: ='List of HBM Equipment'!B205 -> Model | C1: ='List of HBM Equipment'!C371 -> S/N or Asset number | E1: Booked Out
A2: =#REF! -> #REF! | B2: =#REF! -> #REF! | C2: =#REF! -> #REF! | E2: Name | F2: Student Number | G2: Date Taken | H2: Date Returned
B5: Click to return to HOME

Sheet 380114
A1: ='List of HBM Equipment'!A205 -> Type | B1: ='List of HBM Equipment'!B205 -> Model | C1: ='List of HBM Equipment'!C371 -> S/N or Asset number | E1: Booked Out
A2: ='List of HBM Equipment'!A380 -> Agilent | B2: ='List of HBM Equipment'!B380 -> 34970A | C2: 380114 | E2: Name | F2: Student Number | G2: Date Taken | H2: Date Returned
B5: Click to return to HOME

Sheet 404058
A1: ='List of HBM Equipment'!A205 -> Type | B1: ='List of HBM Equipment'!B205 -> Model | C1: ='List of HBM Equipment'!C371 -> S/N or Asset number | E1: Booked Out
A2: ='List of HBM Equipment'!A379 -> Agilent | B2: ='List of HBM Equipment'!B379 -> 34970A | C2: 404058 | E2: Name | F2: Student Number | G2: Date Taken | H2: Date Returned
B5: Click to return to HOME

Sheet 398470
A1: ='List of HBM Equipment'!A205 -> Type | B1: ='List of HBM Equipment'!B205 -> Model | C1: ='List of HBM Equipment'!C371 -> S/N or Asset number | E1: Booked Out
A2: ='List of HBM Equipment'!A378 -> Agilent | B2: ='List of HBM Equipment'!B378 -> 34970A | C2: 398470 | E2: Name | F2: Student Number | G2: Date Taken | H2: Date Returned
B5: Click to return to HOME

Sheet 347346
A1: ='List of HBM Equipment'!A205 -> Type | B1: ='List of HBM Equipment'!B205 -> Model | C1: ='List of HBM Equipment'!C371 -> S/N or Asset number | E1: Booked Out
A2: ='List of HBM Equipment'!A377 -> HP | B2: ='List of HBM Equipment'!B377 -> 34970A | C2: 347346 | E2: Name | F2: Student Number | G2: Date Taken | H2: Date Returned
B5: Click to return to HOME

Sheet 435495
A1: ='List of HBM Equipment'!A205 -> Type | B1: ='List of HBM Equipment'!B205 -> Model | C1: ='List of HBM Equipment'!C371 -> S/N or Asset number | E1: Booked Out
A2: ='List of HBM Equipment'!A376 -> Agilent | B2: ='List of HBM Equipment'!B376 -> 34972A | C2: 435495 | E2: Name | F2: Student Number | G2: Date Taken | H2: Date Returned
B5: Click to return to HOME

Sheet 435461
A1: ='List of HBM Equipment'!A205 -> Type | B1: ='List of HBM Equipment'!B205 -> Model | C1: ='List of HBM Equipment'!C371 -> S/N or Asset number | E1: Booked Out
A2: ='List of HBM Equipment'!A375 -> Agilent | B2: ='List of HBM Equipment'!B375 -> 34972A | C2: 435461 | E2: Name | F2: Student Number | G2: Date Taken | H2: Date Returned
B5: Click to return to HOME

Sheet 410434
A1: ='List of HBM Equipment'!A205 -> Type | B1: ='List of HBM Equipment'!B205 -> Model | C1: ='List of HBM Equipment'!C371 -> S/N or Asset number | E1: Booked Out
A2: ='List of HBM Equipment'!A374 -> Agilent | B2: ='List of HBM Equipment'!B374 -> 34970A | C2: 410434 | E2: Name | F2: Student Number | G2: Date Taken | H2: Date Returned
B5: Click to return to HOME

Sheet 286392
A1: ='List of HBM Equipment'!A205 -> Type | B1: ='List of HBM Equipment'!B205 -> Model | C1: ='List of HBM Equipment'!C371 -> S/N or Asset number | E1: Booked Out
A2: ='List of HBM Equipment'!A373 -> Agilent | B2: ='List of HBM Equipment'!B373 -> 34970A | C2: 286392 | E2: Name | F2: Student Number | G2: Date Taken | H2: Date Returned
B5: Click to return to HOME

Sheet 414110
A1: ='List of HBM Equipment'!A205 -> Type | B1: ='List of HBM Equipment'!B205 -> Model | C1: ='List of HBM Equipment'!C371 -> S/N or Asset number | E1: Booked Out
A2: ='List of HBM Equipment'!A372 -> Agilent | B2: ='List of HBM Equipment'!B372 -> 34970A | C2: 414110 | E2: Name | F2: Student Number | G2: Date Taken | H2: Date Returned
B5: Click to return to HOME

Sheet 247293
A1: ='List of HBM Equipment'!A205 -> Type | B1: ='List of HBM Equipment'!B205 -> Model | C1: ='List of HBM Equipment'!C348 -> S/N or Asset number | E1: Booked Out
A2: ='List of HBM Equipment'!A368 -> Endress+Hauser | B2: ='List of HBM Equipment'!B368 -> Deltabar S PMD130 | C2: 247293 | E2: Name | F2: Student Number | G2: Date Taken | H2: Date Returned
B5: Click to return to HOME

Sheet 216485
A1: ='List of HBM Equipment'!A205 -> Type | B1: ='List of HBM Equipment'!B205 -> Model | C1: ='List of HBM Equipment'!C348 -> S/N or Asset number | E1: Booked Out
A2: ='List of HBM Equipment'!A367 -> Endress+Hauser | B2: ='List of HBM Equipment'!B367 -> Deltabar S PMD130 | C2: 216485 | E2: Name | F2: Student Number | G2: Date Taken | H2: Date Returned
B5: Click to return to HOME

Sheet KC00A421121
A1: ='List of HBM Equipment'!A205 -> Type | B1: ='List of HBM Equipment'!B205 -> Model | C1: ='List of HBM Equipment'!C348 -> S/N or Asset number | E1: Booked Out
A2: ='List of HBM Equipment'!A366 -> Endress+Hauser | B2: ='List of HBM Equipment'!B366 -> Deltabar PMD55 | C2: KC00A421121 | E2: Name | F2: Student Number | G2: Date Taken | H2: Date Returned
B5: Click to return to HOME

Sheet 457162
A1: ='List of HBM Equipment'!A205 -> Type | B1: ='List of HBM Equipment'!B205 -> Model | C1: ='List of HBM Equipment'!C348 -> S/N or Asset number | E1: Booked Out
A2: ='List of HBM Equipment'!A365 -> Endress+Hauser | B2: ='List of HBM Equipment'!B365 -> Deltabar PMD55 | C2: 457162 | E2: Name | F2: Student Number | G2: Date Taken | H2: Date Returned
B5: Click to return to HOME

Sheet 457163
A1: ='List of HBM Equipment'!A205 -> Type | B1: ='List of HBM Equipment'!B205 -> Model | C1: ='List of HBM Equipment'!C348 -> S/N or Asset number | E1: Booked Out
A2: ='List of HBM Equipment'!A363 -> Endress+Hauser | B2: ='List of HBM Equipment'!B363 -> Deltabar PMD55 | C2: 457163 | E2: Name | F2: Student Number | G2: Date Taken | H2: Date Returned
B5: Click to return to HOME

Sheet KC00A221121
A1: ='List of HBM Equipment'!A205 -> Type | B1: ='List of HBM Equipment'!B205 -> Model | C1: ='List of HBM Equipment'!C348 -> S/N or Asset number | E1: Booked Out
A2: ='List of HBM Equipment'!A364 -> Endress+Hauser | B2: ='List of HBM Equipment'!B364 -> Deltabar PMD55 | C2: KC00A221121 | E2: Name | F2: Student Number | G2: Date Taken | H2: Date Returned
B5: Click to return to HOME

Sheet 457157
A1: ='List of HBM Equipment'!A205 -> Type | B1: ='List of HBM Equipment'!B205 -> Model | C1: ='List of HBM Equipment'!C348 -> S/N or Asset number | E1: Booked Out
A2: ='List of HBM Equipment'!A362 -> Endress+Hauser | B2: ='List of HBM Equipment'!B362 -> Deltabar PMD55 | C2: 457157 | E2: Name | F2: Student Number | G2: Date Taken | H2: Date Returned
B5: Click to return to HOME

Sheet 457158
A1: ='List of HBM Equipment'!A205 -> Type | B1: ='List of HBM Equipment'!B205 -> Model | C1: ='List of HBM Equipment'!C348 -> S/N or Asset number | E1: Booked Out
A2: ='List of HBM Equipment'!A361 -> Endress+Hauser | B2: ='List of HBM Equipment'!B361 -> Deltabar PMD55 | C2: 457158 | E2: Name | F2: Student Number | G2: Date Taken | H2: Date Returned
B5: Click to return to HOME

Sheet 457160
A1: ='List of HBM Equipment'!A205 -> Type | B1: ='List of HBM Equipment'!B205 -> Model | C1: ='List of HBM Equipment'!C348 -> S/N or Asset number | E1: Booked Out
A2: ='List of HBM Equipment'!A360 -> Endress+Hauser | B2: ='List of HBM Equipment'!B360 -> Deltabar PMD55 | C2: 457160 | E2: Name | F2: Student Number | G2: Date Taken | H2: Date Returned
B5: Click to return to HOME

Sheet KC009F21121
A1: ='List of HBM Equipment'!A205 -> Type | B1: ='List of HBM Equipment'!B205 -> Model | C1: ='List of HBM Equipment'!C348 -> S/N or Asset number | E1: Booked Out
A2: ='List of HBM Equipment'!A359 -> Endress+Hauser | B2: ='List of HBM Equipment'!B359 -> Deltabar PMD55 | C2: KC009F21121 | E2: Name | F2: Student Number | G2: Date Taken | H2: Date Returned
B5: Click to return to HOME

Sheet 457161
A1: ='List of HBM Equipment'!A205 -> Type | B1: ='List of HBM Equipment'!B205 -> Model | C1: ='List of HBM Equipment'!C348 -> S/N or Asset number | E1: Booked Out
A2: ='List of HBM Equipment'!A358 -> Endress+Hauser | B2: ='List of HBM Equipment'!B358 -> Deltabar PMD55 | C2: 457161 | E2: Name | F2: Student Number | G2: Date Taken | H2: Date Returned
B5: Click to return to HOME

Sheet 156274
A1: ='List of HBM Equipment'!A205 -> Type | B1: ='List of HBM Equipment'!B205 -> Model | C1: ='List of HBM Equipment'!C348 -> S/N or Asset number | E1: Booked Out
A2: ='List of HBM Equipment'!A357 -> Foxboro | B2: ='List of HBM Equipment'!B357 -> 823DP | C2: 156274 | E2: Name | F2: Student Number | G2: Date Taken | H2: Date Returned
B5: Click to return to HOME

Sheet KC00A321121
A1: ='List of HBM Equipment'!A205 -> Type | B1: ='List of HBM Equipment'!B205 -> Model | C1: ='List of HBM Equipment'!C348 -> S/N or Asset number | E1: Booked Out
A2: ='List of HBM Equipment'!A356 -> Endress+Hauser | B2: ='List of HBM Equipment'!B356 -> Deltabar PMD55 | C2: KC00A321121 | E2: Name | F2: Student Number | G2: Date Taken | H2: Date Returned
B5: Click to return to HOME

Sheet 247294
A1: ='List of HBM Equipment'!A205 -> Type | B1: ='List of HBM Equipment'!B205 -> Model | C1: ='List of HBM Equipment'!C348 -> S/N or Asset number | E1: Booked Out
A2: ='List of HBM Equipment'!A355 -> Endress+Hauser | B2: ='List of HBM Equipment'!B355 -> Deltabar S PMD130 | C2: 247294 | E2: Name | F2: Student Number | G2: Date Taken | H2: Date Returned
B5: Click to return to HOME

Sheet 315727
A1: ='List of HBM Equipment'!A205 -> Type | B1: ='List of HBM Equipment'!B205 -> Model | C1: ='List of HBM Equipment'!C348 -> S/N or Asset number | E1: Booked Out
A2: ='List of HBM Equipment'!A354 -> Endress+Hauser | B2: ='List of HBM Equipment'!B354 -> Deltabar S PMD230 | C2: 315727 | E2: Name | F2: Student Number | G2: Date Taken | H2: Date Returned
B5: Click to return to HOME

Sheet 315728
A1: ='List of HBM Equipment'!A205 -> Type | B1: ='List of HBM Equipment'!B205 -> Model | C1: ='List of HBM Equipment'!C348 -> S/N or Asset number | E1: Booked Out
A2: ='List of HBM Equipment'!A353 -> Endress+Hauser | B2: ='List of HBM Equipment'!B353 -> Deltabar S PMD230 | C2: 315728 | E2: Name | F2: Student Number | G2: Date Taken | H2: Date Returned
B5: Click to return to HOME

Sheet 435600
A1: ='List of HBM Equipment'!A205 -> Type | B1: ='List of HBM Equipment'!B205 -> Model | C1: ='List of HBM Equipment'!C348 -> S/N or Asset number | E1: Booked Out
A2: ='List of HBM Equipment'!A352 -> Endress+Hauser | B2: ='List of HBM Equipment'!B352 -> Deltabar S PMD75 | C2: 435600 | E2: Name | F2: Student Number | G2: Date Taken | H2: Date Returned
B5: Click to return to HOME

Sheet 408471
A1: ='List of HBM Equipment'!A205 -> Type | B1: ='List of HBM Equipment'!B205 -> Model | C1: ='List of HBM Equipment'!C348 -> S/N or Asset number | E1: Booked Out
A2: ='List of HBM Equipment'!A351 -> Endress+Hauser | B2: ='List of HBM Equipment'!B351 -> Deltabar S PMD75 | C2: 408471 | E2: Name | F2: Student Number | G2: Date Taken | H2: Date Returned
B5: Click to return to HOME

Sheet 408472
A1: ='List of HBM Equipment'!A205 -> Type | B1: ='List of HBM Equipment'!B205 -> Model | C1: ='List of HBM Equipment'!C348 -> S/N or Asset number | E1: Booked Out
A2: ='List of HBM Equipment'!A349 -> Endress+Hauser | B2: ='List of HBM Equipment'!B349 -> Deltabar S PMD75 | C2: 435601 | E2: Name | F2: Student Number | G2: Date Taken | H2: Date Returned
B5: Click to return to HOME

Sheet 435601
A1: ='List of HBM Equipment'!A205 -> Type | B1: ='List of HBM Equipment'!B205 -> Model | C1: ='List of HBM Equipment'!C348 -> S/N or Asset number | E1: Booked Out
A2: ='List of HBM Equipment'!A349 -> Endress+Hauser | B2: ='List of HBM Equipment'!B349 -> Deltabar S PMD75 | C2: 435601 | E2: Name | F2: Student Number | G2: Date Taken | H2: Date Returned
B5: Click to return to HOME

Sheet 25021
A1: ='List of HBM Equipment'!A205 -> Type | B1: ='List of HBM Equipment'!B205 -> Model | C1: ='List of HBM Equipment'!C335 -> F.Nr. | E1: Booked Out
A2: ='List of HBM Equipment'!A345 -> HBM | B2: ='List of HBM Equipment'!B345 -> PD1 | C2: 25021 | E2: Name | F2: Student Number | G2: Date Taken | H2: Date Returned
B5: Click to return to HOME

Sheet 25023
A1: ='List of HBM Equipment'!A205 -> Type | B1: ='List of HBM Equipment'!B205 -> Model | C1: ='List of HBM Equipment'!C335 -> F.Nr. | E1: Booked Out
A2: ='List of HBM Equipment'!A344 -> HBM | B2: ='List of HBM Equipment'!B344 -> PD1 | C2: 25023 | E2: Name | F2: Student Number | G2: Date Taken | H2: Date Returned
B5: Click to return to HOME

Sheet 25022
A1: ='List of HBM Equipment'!A205 -> Type | B1: ='List of HBM Equipment'!B205 -> Model | C1: ='List of HBM Equipment'!C335 -> F.Nr. | E1: Booked Out
A2: ='List of HBM Equipment'!A343 -> HBM | B2: ='List of HBM Equipment'!B343 -> PD1 | C2: 25022 | E2: Name | F2: Student Number | G2: Date Taken | H2: Date Returned
B5: Click to return to HOME

Sheet 29444
A1: ='List of HBM Equipment'!A205 -> Type | B1: ='List of HBM Equipment'!B205 -> Model | C1: ='List of HBM Equipment'!C335 -> F.Nr. | E1: Booked Out
A2: ='List of HBM Equipment'!A342 -> HBM | B2: ='List of HBM Equipment'!B342 -> PD1 | C2: 29444 | E2: Name | F2: Student Number | G2: Date Taken | H2: Date Returned
B5: Click to return to HOME

Sheet 44609
A1: ='List of HBM Equipment'!A205 -> Type | B1: ='List of HBM Equipment'!B205 -> Model | C1: ='List of HBM Equipment'!C335 -> F.Nr. | E1: Booked Out
A2: ='List of HBM Equipment'!A341 -> HBM | B2: ='List of HBM Equipment'!B341 -> PD1 | C2: 44609 | E2: Name | F2: Student Number | G2: Date Taken | H2: Date Returned
B5: Click to return to HOME

Sheet 48840
A1: ='List of HBM Equipment'!A205 -> Type | B1: ='List of HBM Equipment'!B205 -> Model | C1: ='List of HBM Equipment'!C335 -> F.Nr. | E1: Booked Out
A2: ='List of HBM Equipment'!A340 -> HBM | B2: ='List of HBM Equipment'!B340 -> PD1 | C2: 48840 | E2: Name | F2: Student Number | G2: Date Taken | H2: Date Returned
B5: Click to return to HOME

Sheet 12056
A1: ='List of HBM Equipment'!A205 -> Type | B1: ='List of HBM Equipment'!B205 -> Model | C1: ='List of HBM Equipment'!C335 -> F.Nr. | E1: Booked Out
A2: ='List of HBM Equipment'!A339 -> HBM | B2: ='List of HBM Equipment'!B339 -> PD1 | C2: 12056 | E2: Name | F2: Student Number | G2: Date Taken | H2: Date Returned
B5: Click to return to HOME

Sheet 2931
A1: ='List of HBM Equipment'!A205 -> Type | B1: ='List of HBM Equipment'!B205 -> Model | C1: ='List of HBM Equipment'!C335 -> F.Nr. | E1: Booked Out
A2: ='List of HBM Equipment'!A338 -> HBM | B2: ='List of HBM Equipment'!B338 -> PD1/001 | C2: 2931 | E2: Name | F2: Student Number | G2: Date Taken | H2: Date Returned
B5: Click to return to HOME

Sheet 50070
A1: ='List of HBM Equipment'!A205 -> Type | B1: ='List of HBM Equipment'!B205 -> Model | C1: ='List of HBM Equipment'!C335 -> F.Nr. | E1: Booked Out
A2: ='List of HBM Equipment'!A337 -> HBM | B2: ='List of HBM Equipment'!B337 -> PD1 | C2: 50070 | E2: Name | F2: Student Number | G2: Date Taken | H2: Date Returned
B5: Click to return to HOME

Sheet 6954
A1: ='List of HBM Equipment'!A205 -> Type | B1: ='List of HBM Equipment'!B205 -> Model | C1: ='List of HBM Equipment'!C335 -> F.Nr. | E1: Booked Out
A2: ='List of HBM Equipment'!A336 -> HBM | B2: ='List of HBM Equipment'!B336 -> PD1 | C2: 6954 | E2: Name | F2: Student Number | G2: Date Taken | H2: Date Returned
B5: Click to return to HOME

Sheet 742531
A1: ='List of HBM Equipment'!A205 -> Type | B1: ='List of HBM Equipment'!B205 -> Model | C1: ='List of HBM Equipment'!C205 -> Serial Number | E1: Booked Out
A2: ='List of HBM Equipment'!A332 -> Topward | B2: ='List of HBM Equipment'!B332 -> 6306D | C2: 742531 | E2: Name | F2: Student Number | G2: Date Taken | H2: Date Returned
B5: Click to return to HOME

Sheet 362885
A1: ='List of HBM Equipment'!A205 -> Type | B1: ='List of HBM Equipment'!B205 -> Model | C1: ='List of HBM Equipment'!C205 -> Serial Number | E1: Booked Out
A2: ='List of HBM Equipment'!A331 -> Topward | B2: ='List of HBM Equipment'!B331 -> 6306D | C2: 362885 | E2: Name | F2: Student Number | G2: Date Taken | H2: Date Returned
B5: Click to return to HOME

Sheet 362882
A1: ='List of HBM Equipment'!A205 -> Type | B1: ='List of HBM Equipment'!B205 -> Model | C1: ='List of HBM Equipment'!C205 -> Serial Number | E1: Booked Out
A2: ='List of HBM Equipment'!A330 -> Topward | B2: ='List of HBM Equipment'!B330 -> 6306D | C2: 362882 | E2: Name | F2: Student Number | G2: Date Taken | H2: Date Returned
B5: Click to return to HOME

Sheet 376791
A1: ='List of HBM Equipment'!A205 -> Type | B1: ='List of HBM Equipment'!B205 -> Model | C1: ='List of HBM Equipment'!C205 -> Serial Number | E1: Booked Out
A2: ='List of HBM Equipment'!A329 -> Topward | B2: ='List of HBM Equipment'!B329 -> 6306D | C2: 376791 | E2: Name | F2: Student Number | G2: Date Taken | H2: Date Returned
B5: Click to return to HOME

Sheet MT 395480
A1: ='List of HBM Equipment'!A205 -> Type | B1: ='List of HBM Equipment'!B205 -> Model | C1: ='List of HBM Equipment'!C205 -> Serial Number | E1: Booked Out
A2: ='List of HBM Equipment'!A328 -> Topward | B2: ='List of HBM Equipment'!B328 -> 6306D | C2: MT 395480 | E2: Name | F2: Student Number | G2: Date Taken | H2: Date Returned
B5: Click to return to HOME

Sheet 409517
A1: ='List of HBM Equipment'!A205 -> Type | B1: ='List of HBM Equipment'!B205 -> Model | C1: ='List of HBM Equipment'!C205 -> Serial Number | E1: Booked Out
A2: ='List of HBM Equipment'!A327 -> Topward | B2: ='List of HBM Equipment'!B327 -> 6306D | C2: 409517 | E2: Name | F2: Student Number | G2: Date Taken | H2: Date Returned
B5: Click to return to HOME

Sheet 396333
A1: ='List of HBM Equipment'!A205 -> Type | B1: ='List of HBM Equipment'!B205 -> Model | C1: ='List of HBM Equipment'!C205 -> Serial Number | E1: Booked Out
A2: ='List of HBM Equipment'!A326 -> Topward | B2: ='List of HBM Equipment'!B326 -> 6306D | C2: 396333 | E2: Name | F2: Student Number | G2: Date Taken | H2: Date Returned
B5: Click to return to HOME

Sheet 362883
A1: ='List of HBM Equipment'!A205 -> Type | B1: ='List of HBM Equipment'!B205 -> Model | C1: ='List of HBM Equipment'!C205 -> Serial Number | E1: Booked Out
A2: ='List of HBM Equipment'!A325 -> Topward | B2: ='List of HBM Equipment'!B325 -> 6306D | C2: 362883 | E2: Name | F2: Student Number | G2: Date Taken | H2: Date Returned
B5: Click to return to HOME

Sheet 362884
A1: ='List of HBM Equipment'!A205 -> Type | B1: ='List of HBM Equipment'!B205 -> Model | C1: ='List of HBM Equipment'!C205 -> Serial Number | E1: Booked Out
A2: ='List of HBM Equipment'!A324 -> Topward | B2: ='List of HBM Equipment'!B324 -> 6306D | C2: 362884 | E2: Name | F2: Student Number | G2: Date Taken | H2: Date Returned
B5: Click to return to HOME

Sheet 395480
A1: ='List of HBM Equipment'!A205 -> Type | B1: ='List of HBM Equipment'!B205 -> Model | C1: ='List of HBM Equipment'!C205 -> Serial Number | E1: Booked Out
A2: ='List of HBM Equipment'!A323 -> Topward | B2: ='List of HBM Equipment'!B323 -> 6306D | C2: 395480 | E2: Name | F2: Student Number | G2: Date Taken | H2: Date Returned
B5: Click to return to HOME

Sheet 409513
A1: ='List of HBM Equipment'!A205 -> Type | B1: ='List of HBM Equipment'!B205 -> Model | C1: ='List of HBM Equipment'!C205 -> Serial Number | E1: Booked Out
A2: ='List of HBM Equipment'!A322 -> Topward | B2: ='List of HBM Equipment'!B322 -> 6306D | C2: 409513 | E2: Name | F2: Student Number | G2: Date Taken | H2: Date Returned
B5: Click to return to HOME

Sheet 362886
A1: ='List of HBM Equipment'!A205 -> Type | B1: ='List of HBM Equipment'!B205 -> Model | C1: ='List of HBM Equipment'!C205 -> Serial Number | E1: Booked Out
A2: ='List of HBM Equipment'!A321 -> Topward | B2: ='List of HBM Equipment'!B321 -> 6306D | C2: 362886 | E2: Name | F2: Student Number | G2: Date Taken | H2: Date Returned
B5: Click to return to HOME

Sheet SN HB7198628
A1: ='List of HBM Equipment'!A205 -> Type | B1: ='List of HBM Equipment'!B205 -> Model | C1: ='List of HBM Equipment'!C205 -> Serial Number | E1: Booked Out
A2: ='List of HBM Equipment'!A309 -> National Instruments | B2: ='List of HBM Equipment'!B309 -> cDAQ-9171 | C2: SN: HB7198628 | E2: Name | F2: Student Number | G2: Date Taken | H2: Date Returned
B5: Click to return to HOME

Sheet 801182A-01
A1: ='List of HBM Equipment'!A205 -> Type | B1: ='List of HBM Equipment'!B205 -> Model | C1: ='List of HBM Equipment'!C205 -> Serial Number | E1: Booked Out
A2: ='List of HBM Equipment'!A313 -> National Instruments | B2: ='List of HBM Equipment'!B313 -> NI myRIO | C2: 801182A-01 | E2: Name | F2: Student Number | G2: Date Taken | H2: Date Returned
B5: Click to return to HOME

Sheet SN HB7127916
A1: ='List of HBM Equipment'!A205 -> Type | B1: ='List of HBM Equipment'!B205 -> Model | C1: ='List of HBM Equipment'!C205 -> Serial Number | E1: Booked Out
A2: ='List of HBM Equipment'!A308 -> National Instruments | B2: ='List of HBM Equipment'!B308 -> cDAQ-9171 | C2: SN: HB7127916 | E2: Name | F2: Student Number | G2: Date Taken | H2: Date Returned
B5: Click to return to HOME

Sheet SN HC7742072
A1: ='List of HBM Equipment'!A205 -> Type | B1: ='List of HBM Equipment'!B205 -> Model | C1: ='List of HBM Equipment'!C205 -> Serial Number | E1: Booked Out
A2: ='List of HBM Equipment'!A304 -> National Instruments | B2: ='List of HBM Equipment'!B304 -> NI 9215 | C2: SN: HC7742072 | E2: Name | F2: Student Number | G2: Date Taken | H2: Date Returned
B5: Click to return to HOME

Sheet SN HC3654124
A1: ='List of HBM Equipment'!A205 -> Type | B1: ='List of HBM Equipment'!B205 -> Model | C1: ='List of HBM Equipment'!C205 -> Serial Number | E1: Booked Out
A2: ='List of HBM Equipment'!A295 -> National Instruments | B2: ='List of HBM Equipment'!B295 -> NI USB-6212 | C2: SN: HC3654124 | E2: Name | F2: Student Number | G2: Date Taken | H2: Date Returned
B5: Click to return to HOME

Sheet SN 1313704018F
A1: ='List of HBM Equipment'!A205 -> Type | B1: ='List of HBM Equipment'!B205 -> Model | C1: ='List of HBM Equipment'!C205 -> Serial Number | E1: Booked Out
A2: ='List of HBM Equipment'!A300 -> SICK | B2: ='List of HBM Equipment'!B300 -> OD1-B035C15I25 | C2: S/N 1313704018F | E2: Name | F2: Student Number | G2: Date Taken | H2: Date Returned
B5: Click to return to HOME

Sheet SN 1313704020F
A1: ='List of HBM Equipment'!A205 -> Type | B1: ='List of HBM Equipment'!B205 -> Model | C1: ='List of HBM Equipment'!C205 -> Serial Number | E1: Booked Out
A2: ='List of HBM Equipment'!A299 -> SICK | B2: ='List of HBM Equipment'!B299 -> OD1-B035C15I25 | C2: S/N 1313704020F | E2: Name | F2: Student Number | G2: Date Taken | H2: Date Returned
B5: Click to return to HOME

Sheet SN PA1069944
A1: ='List of HBM Equipment'!A205 -> Type | B1: ='List of HBM Equipment'!B205 -> Model | C1: ='List of HBM Equipment'!C205 -> Serial Number | E1: Booked Out
A2: ='List of HBM Equipment'!A294 -> National Instruments | B2: ='List of HBM Equipment'!B294 -> NI USB-6009 | C2: SN: PA1069944 | E2: Name | F2: Student Number | G2: Date Taken | H2: Date Returned
B5: Click to return to HOME

Sheet SN HB8462936
A1: ='List of HBM Equipment'!A205 -> Type | B1: ='List of HBM Equipment'!B205 -> Model | C1: ='List of HBM Equipment'!C205 -> Serial Number | E1: Booked Out
A2: ='List of HBM Equipment'!A293 -> National Instruments | B2: ='List of HBM Equipment'!B293 -> NI USB-6009 | C2: SN: HB8462936 | E2: Name | F2: Student Number | G2: Date Taken | H2: Date Returned
B5: Click to return to HOME

Sheet FU8240115
A1: ='List of HBM Equipment'!A205 -> Type | B1: ='List of HBM Equipment'!B205 -> Model | C1: ='List of HBM Equipment'!C205 -> Serial Number | E1: Booked Out
A2: ='List of HBM Equipment'!A288 -> PicoTech | B2: ='List of HBM Equipment'!B288 -> 4444 | C2: FU824/0115 | E2: Name | F2: Student Number | G2: Date Taken | H2: Date Returned
B5: Click to return to HOME

Sheet 378350
A1: ='List of HBM Equipment'!A205 -> Type | B1: ='List of HBM Equipment'!B205 -> Model | C1: ='List of HBM Equipment'!C205 -> Serial Number | E1: Booked Out
A2: ='List of HBM Equipment'!A242 -> Nova-strobe | B2: ='List of HBM Equipment'!B242 -> DB plus kit 230 | C2: 378350 | E2: Name | F2: Student Number | G2: Date Taken | H2: Date Returned
B5: Click to return to HOME

Sheet 08090004
A1: ='List of HBM Equipment'!A205 -> Type | B1: ='List of HBM Equipment'!B205 -> Model | C1: ='List of HBM Equipment'!C205 -> Serial Number | E1: Booked Out
A2: ='List of HBM Equipment'!A238 -> Major Tech | B2: ='List of HBM Equipment'!B238 -> MT948 | C2: 08090004 | E2: Name | F2: Student Number | G2: Date Taken | H2: Date Returned
B5: Click to return to HOME

Sheet 302635
A1: ='List of HBM Equipment'!A205 -> Type | B1: ='List of HBM Equipment'!B205 -> Model | C1: ='List of HBM Equipment'!C205 -> Serial Number | E1: Booked Out
A2: ='List of HBM Equipment'!A234 -> DRUK METER | B2: ='List of HBM Equipment'!B234 -> WIKA | C2: 302635 | E2: Name | F2: Student Number | G2: Date Taken | H2: Date Returned
B5: Click to return to HOME

Sheet 302637
A1: ='List of HBM Equipment'!A205 -> Type | B1: ='List of HBM Equipment'!B205 -> Model | C1: ='List of HBM Equipment'!C205 -> Serial Number | E1: Booked Out
A2: ='List of HBM Equipment'!A233 -> DRUK METER | B2: ='List of HBM Equipment'!B233 -> WIKA | C2: 302637 | E2: Name | F2: Student Number | G2: Date Taken | H2: Date Returned
E3: A Mentz | F3: 25848306 | G3: 30/06/2025 | H3: OUTSTANDING
B5: Click to return to HOME

Sheet 302636
A1: ='List of HBM Equipment'!A205 -> Type | B1: ='List of HBM Equipment'!B205 -> Model | C1: ='List of HBM Equipment'!C205 -> Serial Number | E1: Booked Out
A2: ='List of HBM Equipment'!A232 -> VAKUUM METER | B2: ='List of HBM Equipment'!B232 -> WIKA | C2: 302636 | E2: Name | F2: Student Number | G2: Date Taken | H2: Date Returned
B5: Click to return to HOME

Sheet 302638
A1: ='List of HBM Equipment'!A205 -> Type | B1: ='List of HBM Equipment'!B205 -> Model | C1: ='List of HBM Equipment'!C205 -> Serial Number | E1: Booked Out
A2: ='List of HBM Equipment'!A228 -> DRUK POMP | B2: ='List of HBM Equipment'!B228 -> 36720 | C2: 302638 | E2: Name | F2: Student Number | G2: Date Taken | H2: Date Returned
B5: Click to return to HOME

Sheet 8711
A1: ='List of HBM Equipment'!A205 -> Type | B1: ='List of HBM Equipment'!B205 -> Model | C1: ='List of HBM Equipment'!C205 -> Serial Number | E1: Booked Out
A2: ='List of HBM Equipment'!A224 -> Lenton Thermo-hygrometer | B2: 8711 | C2: ='List of HBM Equipment'!C224 -> S/N 8804028 | E2: Name | F2: Student Number | G2: Date Taken | H2: Date Returned
B5: Click to return to HOME

Sheet 486012
A1: ='List of HBM Equipment'!A205 -> Type | B1: ='List of HBM Equipment'!B205 -> Model | C1: ='List of HBM Equipment'!C205 -> Serial Number | E1: Booked Out
A2: ='List of HBM Equipment'!A220 -> UNI-T | B2: ='List of HBM Equipment'!B220 -> UTP3305 | C2: 486012 | E2: Name | F2: Student Number | G2: Date Taken | H2: Date Returned
B5: Click to return to HOME

Sheet 486013
A1: ='List of HBM Equipment'!A205 -> Type | B1: ='List of HBM Equipment'!B205 -> Model | C1: ='List of HBM Equipment'!C205 -> Serial Number | E1: Booked Out
A2: ='List of HBM Equipment'!A219 -> UNI-T | B2: ='List of HBM Equipment'!B219 -> UTP3305 | C2: 486013 | E2: Name | F2: Student Number | G2: Date Taken | H2: Date Returned
E3: N Moyo | G3: 44477
B5: Click to return to HOME

Sheet GES871330
A1: ='List of HBM Equipment'!A205 -> Type | B1: ='List of HBM Equipment'!B205 -> Model | C1: ='List of HBM Equipment'!C205 -> Serial Number | E1: Booked Out
A2: ='List of HBM Equipment'!A218 -> GW Instek | B2: ='List of HBM Equipment'!B218 -> GPS-3030 | C2: GES871330 | E2: Name | F2: Student Number | G2: Date Taken | H2: Date Returned
E3: S Singh | F3: 22980644 | G3: 20/09/2022
B5: Click to return to HOME

Sheet GER863120
A1: ='List of HBM Equipment'!A205 -> Type | B1: ='List of HBM Equipment'!B205 -> Model | C1: ='List of HBM Equipment'!C205 -> Serial Number | E1: Booked Out
A2: ='List of HBM Equipment'!A217 -> GW Instek | B2: ='List of HBM Equipment'!B217 -> GPS-3030 | C2: GER863120 | E2: Name | F2: Student Number | G2: Date Taken | H2: Date Returned
E4: T Machtelinck | F4: 23661194 | G4: 22/05/2025 | H4: OUTSTANDING
B5: Click to return to HOME

Sheet GES871343
A1: ='List of HBM Equipment'!A205 -> Type | B1: ='List of HBM Equipment'!B205 -> Model | C1: ='List of HBM Equipment'!C205 -> Serial Number | E1: Booked Out
A2: ='List of HBM Equipment'!A216 -> GW Instek | B2: ='List of HBM Equipment'!B216 -> GPS-3030 | C2: GES871343 | E2: Name | F2: Student Number | G2: Date Taken | H2: Date Returned
E3: Elke Hestermann | G3: 44477
E4: Herman Roux | F4: 22536612 | G4: 20/09/2022
B5: Click to return to HOME

Sheet GES871338
A1: ='List of HBM Equipment'!A205 -> Type | B1: ='List of HBM Equipment'!B205 -> Model | C1: ='List of HBM Equipment'!C205 -> Serial Number | E1: Booked Out
A2: ='List of HBM Equipment'!A215 -> GW Instek | B2: ='List of HBM Equipment'!B215 -> GPS-3030 | C2: GES871338 | E2: Name | F2: Student Number | G2: Date Taken | H2: Date Returned
E3: N Moyo | G3: 44355
E4: R Lekloloane | F4: 21192057 | G4: 45756 | H4: RETURNED
B5: Click to return to HOME

Sheet A376659
A1: ='List of HBM Equipment'!A205 -> Type | B1: ='List of HBM Equipment'!B205 -> Model | C1: ='List of HBM Equipment'!C205 -> Serial Number | E1: Booked Out
A2: ='List of HBM Equipment'!A214 -> Xytron DC power supply | B2: ='List of HBM Equipment'!B214 -> GPC-3030E | C2: A376659 | E2: Name | F2: Student Number | G2: Date Taken | H2: Date Returned
E3: S Van Der Merwe | F3: 22569081 | G3: 22/09/2022
E4: H Janse Van Vuuren | F4: 21642478 | G4: 45741 | H4: OUTSTANDING
B5: Click to return to HOME

Sheet SN 801D200G2
A1: ='List of HBM Equipment'!A205 -> Type | B1: ='List of HBM Equipment'!B205 -> Model | C1: ='List of HBM Equipment'!C205 -> Serial Number | E1: Booked Out
A2: ='List of HBM Equipment'!A213 -> ISO-TECH | B2: ='List of HBM Equipment'!B213 -> IPS-2303 | C2: S/N 801D200G2 | E2: Name | F2: Student Number | G2: Date Taken | H2: Date Returned
B5: Click to return to HOME

Sheet SN EN850209
A1: ='List of HBM Equipment'!A205 -> Type | B1: ='List of HBM Equipment'!B205 -> Model | C1: ='List of HBM Equipment'!C205 -> Serial Number | E1: Booked Out
A2: ='List of HBM Equipment'!A212 -> GW Instek | B2: ='List of HBM Equipment'!B212 -> SPD-3606 | C2: S/N EN850209 | E2: Name | F2: Student Number | G2: Date Taken | H2: Date Returned
E3: Jacob Wasserfall | F3: 20689810 | G3: 44324 | H3: RETURNED
E4: Jacques Wessels | F4: 16801594 | G4: 30/03/2022 | H4: RETURNED
B5: Click to return to HOME | E5: A J.V Rensburg | F5: 24726265 | G5: 45756 | H5: OUTSTANDING

Sheet SN 6271507451
A1: ='List of HBM Equipment'!A205 -> Type | B1: ='List of HBM Equipment'!B205 -> Model | C1: ='List of HBM Equipment'!C205 -> Serial Number | E1: Booked Out
A2: ='List of HBM Equipment'!A211 -> Manson DC power supply | B2: ='List of HBM Equipment'!B211 -> HCS-3202 | C2: S/N 6271507451 | E2: Name | F2: Student Number | G2: Date Taken | H2: Date Returned
B5: Click to return to HOME

Sheet SN 6271507452
A1: ='List of HBM Equipment'!A205 -> Type | B1: ='List of HBM Equipment'!B205 -> Model | C1: ='List of HBM Equipment'!C205 -> Serial Number | E1: Booked Out
A2: ='List of HBM Equipment'!A210 -> Manson DC power supply | B2: ='List of HBM Equipment'!B210 -> HCS-3202 | C2: S/N 6271507452 | E2: Name | F2: Student Number | G2: Date Taken | H2: Date Returned
B5: Click to return to HOME

Sheet FG-6020SD
A1: ='List of HBM Equipment'!A205 -> Type | B1: ='List of HBM Equipment'!B205 -> Model | C1: ='List of HBM Equipment'!C205 -> Serial Number | E1: Booked Out
A2: ='List of HBM Equipment'!A206 -> Lutron | B2: FG-6020SD | C2: ='List of HBM Equipment'!C206 -> L1608047 | E2: Name | F2: Student Number | G2: Date Taken | H2: Date Returned
B5: Click to return to HOME

Sheet R150037479
A1: Type | B1: Model | C1: Serial Number | E1: Booked Out
A2: ='List of HBM Equipment'!A202 -> UNI-T | B2: ='List of HBM Equipment'!B202 -> UT61E | C2: R150037479 | E2: Name | F2: Student Number | G2: Date Taken | H2: Date Returned
B5: Click to return to HOME

Sheet R150028739
A1: Type | B1: Model | C1: Serial Number | E1: Booked Out
A2: ='List of HBM Equipment'!A201 -> UNI-T | B2: ='List of HBM Equipment'!B201 -> UT61E | C2: ='List of HBM Equipment'!C201 -> R150028739 | E2: Name | F2: Student Number | G2: Date Taken | H2: Date Returned
B5: Click to return to HOME

Sheet R150028740
A1: Type | B1: Model | C1: Serial Number | E1: Booked Out
A2: ='List of HBM Equipment'!A200 -> UNI-T | B2: ='List of HBM Equipment'!B200 -> UT61E | C2: R150028740 | E2: Name | F2: Student Number | G2: Date Taken | H2: Date Returned
B5: Click to return to HOME

Sheet UM 180791
A1: Type | B1: Model | C1: Serial Number | E1: Booked Out
A2: ='List of HBM Equipment'!A199 -> GW Instek | B2: ='List of HBM Equipment'!B199 -> GDM-396 | C2: UM 180791 | E2: Name | F2: Student Number | G2: Date Taken | H2: Date Returned
B5: Click to return to HOME

Sheet UM 180997
A1: Type | B1: Model | C1: Serial Number | E1: Booked Out
A2: ='List of HBM Equipment'!A198 -> GW Instek | B2: ='List of HBM Equipment'!B198 -> GDM-396 | C2: UM 180997 | E2: Name | F2: Student Number | G2: Date Taken | H2: Date Returned
B5: Click to return to HOME

Sheet 111
A1: Type | B1: Model | C1: Serial Number | E1: Booked Out
A2: ='List of HBM Equipment'!A197 -> Fluke | B2: 111 | C2: ='List of HBM Equipment'!C197 -> 0 | E2: Name | F2: Student Number | G2: Date Taken | H2: Date Returned
B5: Click to return to HOME

Sheet CJ187818
A1: Type | B1: Model | C1: Serial Number | E1: Booked Out
A2: ='List of HBM Equipment'!A196 -> Metex | B2: ='List of HBM Equipment'!B196 -> M-3650 | C2: CJ187818 | E2: Name | F2: Student Number | G2: Date Taken | H2: Date Returned
B5: Click to return to HOME

Sheet 189089
A1: Type | B1: Model | C1: Serial Number | E1: Booked Out
A2: ='List of HBM Equipment'!A195 -> Metex | B2: ='List of HBM Equipment'!B195 -> M-3850D | C2: 189089 | E2: Name | F2: Student Number | G2: Date Taken | H2: Date Returned
B5: Click to return to HOME

Sheet 2911A60173
A1: Type | B1: Model | C1: Serial Number | E1: Booked Out
A2: ='List of HBM Equipment'!A194 -> Hewlett Packard | B2: ='List of HBM Equipment'!B194 -> 3478A | C2: 2911A60173 | E2: Name | F2: Student Number | G2: Date Taken | H2: Date Returned
B5: Click to return to HOME

Sheet 723657
A1: Type | B1: Model | C1: Serial Number | E1: Booked Out
